Traceback (most recent call last):
  File "/Users/udeshhabaraduwa/anaconda3/envs/pyenv/lib/python3.9/site-packages/jupyter_cache/executors/utils.py", line 58, in single_nb_execution
    executenb(
  File "/Users/udeshhabaraduwa/anaconda3/envs/pyenv/lib/python3.9/site-packages/nbclient/client.py", line 1314, in execute
    return NotebookClient(nb=nb, resources=resources, km=km, **kwargs).execute()
  File "/Users/udeshhabaraduwa/anaconda3/envs/pyenv/lib/python3.9/site-packages/jupyter_core/utils/__init__.py", line 166, in wrapped
    return loop.run_until_complete(inner)
  File "/Users/udeshhabaraduwa/anaconda3/envs/pyenv/lib/python3.9/asyncio/base_events.py", line 647, in run_until_complete
    return future.result()
  File "/Users/udeshhabaraduwa/anaconda3/envs/pyenv/lib/python3.9/site-packages/nbclient/client.py", line 709, in async_execute
    await self.async_execute_cell(
  File "/Users/udeshhabaraduwa/anaconda3/envs/pyenv/lib/python3.9/site-packages/nbclient/client.py", line 1062, in async_execute_cell
    await self._check_raise_for_error(cell, cell_index, exec_reply)
  File "/Users/udeshhabaraduwa/anaconda3/envs/pyenv/lib/python3.9/site-packages/nbclient/client.py", line 918, in _check_raise_for_error
    raise CellExecutionError.from_cell_and_msg(cell, exec_reply_content)
nbclient.exceptions.CellExecutionError: An error occurred while executing the following cell:
------------------
# define a function and its derivative
f(x) = x^2
df(x) = 
# generate values from it
out = []
for i in 1:20
    push!(out,f(i))
end
------------------


UndefVarError: `out` not defined

Stacktrace:
 [1] top-level scope
   @ ./In[2]:7

